Workbook

Sheet Controls
A2: Legacy ERP: | B2: Sage 300 CRE
A3: New ERP: | B3: Sage Intacct
A5: Field | B5: Value | C5: [MAP].[E_USEFUL_FIELDS]
A6: GL01_BALANCE_END | B6: 45657 | C6: ="UPDATE "&C$5&" SET FIELD_VALUE = '"&TEXT(B6,"YYYY-MM-DD")&"' WHERE FIELD_NAME = '"&A6&"'" -> UPDATE [MAP].[E_USEFUL_FIELDS] SET FIELD_VALUE = '2024-12-31' WHERE FIELD_NAME = 'GL01_BALANCE_END'
A7: GL02_MONTHLY_START | B7: 45658 | C7: ="UPDATE "&C$5&" SET FIELD_VALUE = '"&TEXT(B7,"YYYY-MM-DD")&"' WHERE FIELD_NAME = '"&A7&"'" -> UPDATE [MAP].[E_USEFUL_FIELDS] SET FIELD_VALUE = '2025-01-01' WHERE FIELD_NAME = 'GL02_MONTHLY_START'
A8: GL02_MONTHLY_STOP | B8: 46022 | C8: ="UPDATE "&C$5&" SET FIELD_VALUE = '"&TEXT(B8,"YYYY-MM-DD")&"' WHERE FIELD_NAME = '"&A8&"'" -> UPDATE [MAP].[E_USEFUL_FIELDS] SET FIELD_VALUE = '2025-12-31' WHERE FIELD_NAME = 'GL02_MONTHLY_STOP'
A9: GL03_DETAIL_START | B9: 46023 | C9: ="UPDATE "&C$5&" SET FIELD_VALUE = '"&TEXT(B9,"YYYY-MM-DD")&"' WHERE FIELD_NAME = '"&A9&"'" -> UPDATE [MAP].[E_USEFUL_FIELDS] SET FIELD_VALUE = '2026-01-01' WHERE FIELD_NAME = 'GL03_DETAIL_START'
A10: GL03_DETAIL_STOP | B10: 46081 | C10: ="UPDATE "&C$5&" SET FIELD_VALUE = '"&TEXT(B10,"YYYY-MM-DD")&"' WHERE FIELD_NAME = '"&A10&"'" -> UPDATE [MAP].[E_USEFUL_FIELDS] SET FIELD_VALUE = '2026-02-28' WHERE FIELD_NAME = 'GL03_DETAIL_STOP'

Sheet Entity
A1: ="Legacy ERP: "&Controls!$B$2 -> Legacy ERP: Sage 300 CRE | C1: ="New ERP: "&Controls!$B$3 -> New ERP: Sage Intacct
A3: Data Folder | B3: Data Folder Description | C3: Entity ID | D3: PKG_BASE | E3: PKG_CONSTR_SUM | F3: PKG_CONSTR_DET | G3: PKG_PAYROLL | H3: PKG_NPC_COMMIT | I3: PKG_PC_COMMIT | J3: [MAP].[T_TRANS_ENTITY] | K3: Change | L3: hide/show
A4: inter | C4: 100 | D4: 1 | E4: 1 | F4: 1 | G4: 0 | H4: 1 | I4: 0 | J4: ="UPDATE "&J$3&" SET NEW_ENTITY_ID = '"&TRIM(C4)&"', PKG_BASE = "&D4&", PKG_CONSTR_SUM = '"&E4&"', PKG_CONSTR_DET = '"&F4&"', PKG_PAYROLL = '"&G4&"', PKG_NPC_COMMIT = '"&H4&"', PKG_PC_COMMIT = '"&I4& "'"&" WHERE Data_Folder_Id = '"&A4&"'" -> UPDATE [MAP].[T_TRANS_ENTITY] SET NEW_ENTITY_ID = '100', PKG_BASE = 1, PKG_CONSTR_SUM = '1', PKG_CONSTR_DET = '1', PKG_PAYROLL = '0', PKG_NPC_COMMIT = '1', PKG_PC_COMMIT = '0' WHERE Data_Folder_Id = 'inter' | K4: =IF(A4<>C4,"Changed","-") -> Changed | L4: =IF(A4="","Hide","-") -> -
A5: paint | C5: 200 | D5: 1 | E5: 1 | F5: 1 | G5: 0 | H5: 0 | I5: 0 | J5: ="UPDATE "&J$3&" SET NEW_ENTITY_ID = '"&TRIM(C5)&"', PKG_BASE = "&D5&", PKG_CONSTR_SUM = '"&E5&"', PKG_CONSTR_DET = '"&F5&"', PKG_PAYROLL = '"&G5&"', PKG_NPC_COMMIT = '"&H5&"', PKG_PC_COMMIT = '"&I5& "'"&" WHERE Data_Folder_Id = '"&A5&"'" -> UPDATE [MAP].[T_TRANS_ENTITY] SET NEW_ENTITY_ID = '200', PKG_BASE = 1, PKG_CONSTR_SUM = '1', PKG_CONSTR_DET = '1', PKG_PAYROLL = '0', PKG_NPC_COMMIT = '0', PKG_PC_COMMIT = '0' WHERE Data_Folder_Id = 'paint' | K5: =IF(A5<>C5,"Changed","-") -> Changed | L5: =IF(A5="","Hide","-") -> -
A6: prem | C6: 300 | D6: 1 | E6: 1 | F6: 1 | G6: 0 | H6: 0 | I6: 0 | J6: ="UPDATE "&J$3&" SET NEW_ENTITY_ID = '"&TRIM(C6)&"', PKG_BASE = "&D6&", PKG_CONSTR_SUM = '"&E6&"', PKG_CONSTR_DET = '"&F6&"', PKG_PAYROLL = '"&G6&"', PKG_NPC_COMMIT = '"&H6&"', PKG_PC_COMMIT = '"&I6& "'"&" WHERE Data_Folder_Id = '"&A6&"'" -> UPDATE [MAP].[T_TRANS_ENTITY] SET NEW_ENTITY_ID = '300', PKG_BASE = 1, PKG_CONSTR_SUM = '1', PKG_CONSTR_DET = '1', PKG_PAYROLL = '0', PKG_NPC_COMMIT = '0', PKG_PC_COMMIT = '0' WHERE Data_Folder_Id = 'prem' | K6: =IF(A6<>C6,"Changed","-") -> Changed | L6: =IF(A6="","Hide","-") -> -

Sheet Job ID
A1: ="Legacy ERP: "&Controls!$B$2 -> Legacy ERP: Sage 300 CRE | E1: ="New ERP: "&Controls!$B$3 -> New ERP: Sage Intacct
A3: Data Folder ID | B3: Job | C3: Job Extra | D3: Job Description | E3: Include? | F3: Job | G3: Entity/Loc ID | H3: Department ID | I3: Class ID | J3: Customer ID | K3: PM ID | L3: [MAP].[T_TRANS_JOB] | M3: Change | N3: hide/show
A4: schi | B4: 14-117 | D4: Laceworks CM Project | E4: Yes | F4: Test001 | G4: PA | H4: Commercial | I4: CM | J4: C0056 | K4: 10024 | L4: ="UPDATE "&L$3&" SET NEW_JOB_ID = '"&TRIM(F4)&"', INCLUDE_JOB = "&IF(E4="Yes",1,0)&", NEW_ENTITY_ID = '"&G4&"', NEW_DEPARTMENT_ID = '"&H4&"', NEW_CLASS_ID = '"&I4&"', NEW_CUSTOMER_ID = '"&J4&"', NEW_PM_ID = '"&K4& "'"&" WHERE LEGACY_JOB_ID = '"&TRIM(B4)&"' AND Data_Folder_Id = '"&A4&"'" -> UPDATE [MAP].[T_TRANS_JOB] SET NEW_JOB_ID = 'Test001', INCLUDE_JOB = 1, NEW_ENTITY_ID = 'PA', NEW_DEPARTMENT_ID = 'Commercial', NEW_CLASS_ID = 'CM', NEW_CUSTOMER_ID = 'C0056', NEW_PM_ID = '10024' WHERE LEGACY_JOB_ID = '14-117' AND Data_Folder_Id = 'schi' | M4: =IF(B4<>F4,"Changed","-") -> Changed | N4: =IF(B4="","Hide","-") -> -
A5: schi | B5: 16-599 | D5: Laceworks Pennvest Storm Water | E5: Yes | F5: Test002 | G5: PA | H5: Commercial | I5: CM | J5: C0056 | K5: 10024 | L5: ="UPDATE "&L$3&" SET NEW_JOB_ID = '"&TRIM(F5)&"', INCLUDE_JOB = "&IF(E5="Yes",1,0)&", NEW_ENTITY_ID = '"&G5&"', NEW_DEPARTMENT_ID = '"&H5&"', NEW_CLASS_ID = '"&I5&"', NEW_CUSTOMER_ID = '"&J5&"', NEW_PM_ID = '"&K5& "'"&" WHERE LEGACY_JOB_ID = '"&TRIM(B5)&"' AND Data_Folder_Id = '"&A5&"'" -> UPDATE [MAP].[T_TRANS_JOB] SET NEW_JOB_ID = 'Test002', INCLUDE_JOB = 1, NEW_ENTITY_ID = 'PA', NEW_DEPARTMENT_ID = 'Commercial', NEW_CLASS_ID = 'CM', NEW_CUSTOMER_ID = 'C0056', NEW_PM_ID = '10024' WHERE LEGACY_JOB_ID = '16-599' AND Data_Folder_Id = 'schi' | M5: =IF(B5<>F5,"Changed","-") -> Changed | N5: =IF(B5="","Hide","-") -> -
A6: schi | B6: 17-005 | D6: COLTS Transit Facility | E6: Yes | F6: Test003 | G6: PA | H6: Commercial | I6: GC | J6: C0022 | K6: 10046 | L6: ="UPDATE "&L$3&" SET NEW_JOB_ID = '"&TRIM(F6)&"', INCLUDE_JOB = "&IF(E6="Yes",1,0)&", NEW_ENTITY_ID = '"&G6&"', NEW_DEPARTMENT_ID = '"&H6&"', NEW_CLASS_ID = '"&I6&"', NEW_CUSTOMER_ID = '"&J6&"', NEW_PM_ID = '"&K6& "'"&" WHERE LEGACY_JOB_ID = '"&TRIM(B6)&"' AND Data_Folder_Id = '"&A6&"'" -> UPDATE [MAP].[T_TRANS_JOB] SET NEW_JOB_ID = 'Test003', INCLUDE_JOB = 1, NEW_ENTITY_ID = 'PA', NEW_DEPARTMENT_ID = 'Commercial', NEW_CLASS_ID = 'GC', NEW_CUSTOMER_ID = 'C0022', NEW_PM_ID = '10046' WHERE LEGACY_JOB_ID = '17-005' AND Data_Folder_Id = 'schi' | M6: =IF(B6<>F6,"Changed","-") -> Changed | N6: =IF(B6="","Hide","-") -> -
A7: schi | B7: 17-101 | D7: Fidelity Bank Corporate HQ | E7: Yes | F7: Test004 | G7: PA | H7: Commercial | I7: CM | J7: C0035 | K7: 10015 | L7: ="UPDATE "&L$3&" SET NEW_JOB_ID = '"&TRIM(F7)&"', INCLUDE_JOB = "&IF(E7="Yes",1,0)&", NEW_ENTITY_ID = '"&G7&"', NEW_DEPARTMENT_ID = '"&H7&"', NEW_CLASS_ID = '"&I7&"', NEW_CUSTOMER_ID = '"&J7&"', NEW_PM_ID = '"&K7& "'"&" WHERE LEGACY_JOB_ID = '"&TRIM(B7)&"' AND Data_Folder_Id = '"&A7&"'" -> UPDATE [MAP].[T_TRANS_JOB] SET NEW_JOB_ID = 'Test004', INCLUDE_JOB = 1, NEW_ENTITY_ID = 'PA', NEW_DEPARTMENT_ID = 'Commercial', NEW_CLASS_ID = 'CM', NEW_CUSTOMER_ID = 'C0035', NEW_PM_ID = '10015' WHERE LEGACY_JOB_ID = '17-101' AND Data_Folder_Id = 'schi' | M7: =IF(B7<>F7,"Changed","-") -> Changed | N7: =IF(B7="","Hide","-") -> -

Sheet GL Account
A1: ="Legacy ERP: "&Controls!$B$2 -> Legacy ERP: Sage 300 CRE | D1: ="New ERP: "&Controls!$B$3 -> New ERP: Sage Intacct
A3: Data Folder ID | B3: GL Account | C3: GL Account Description | D3: GL Account | E3: [MAP].[T_TRANS_BASEACCT] | F3: Change | G3: hide/show
A4: sampl | B4: 1000 | C4: Cash - Petty Cash | D4: 1000 | E4: ="UPDATE "&$E$3&" SET New_Base_Account = '"&D4&"' WHERE Legacy_Base_Account = '"&B4&"' AND Data_Folder_Id = '"&$A4&"'" -> UPDATE [MAP].[T_TRANS_BASEACCT] SET New_Base_Account = '1000' WHERE Legacy_Base_Account = '1000' AND Data_Folder_Id = 'sampl' | F4: =IF(B4<>D4,"Changed","-") -> - | G4: =IF(B4="","Hide","-") -> -
A5: sampl | B5: 1005 | C5: Cash - Fidelity Operations | D5: 1005 | E5: ="UPDATE "&$E$3&" SET New_Base_Account = '"&D5&"' WHERE Legacy_Base_Account = '"&B5&"' AND Data_Folder_Id = '"&$A5&"'" -> UPDATE [MAP].[T_TRANS_BASEACCT] SET New_Base_Account = '1005' WHERE Legacy_Base_Account = '1005' AND Data_Folder_Id = 'sampl' | F5: =IF(B5<>D5,"Changed","-") -> - | G5: =IF(B5="","Hide","-") -> -

Sheet Location ID
A1: ="Legacy ERP: "&Controls!$B$2 -> Legacy ERP: Sage 300 CRE | D1: ="New ERP: "&Controls!$B$3 -> New ERP: Sage Intacct
A3: Data Folder ID | B3: Location | C3: Location Description | D3: Location | E3: [MAP].[T_TRANS_LOCATION] | F3: Change | G3: hide/show
A4: sampl | B4: 1-00 | C4: 1-00 LRC Balance Sheet | D4: E010 | E4: ="UPDATE "&$E$3&" SET New_Location_Id = '"&D4&"' WHERE Legacy_Location_Id = '"&B4&"' AND Data_Folder_Id = '"&$A4&"'" -> UPDATE [MAP].[T_TRANS_LOCATION] SET New_Location_Id = 'E010' WHERE Legacy_Location_Id = '1-00' AND Data_Folder_Id = 'sampl' | F4: =IF(B4<>D4,"Changed","-") -> Changed | G4: =IF(B4="","Hide","-") -> -
A5: sampl | B5: 1-88 | C5: 1-88 Corporate | D5: CO | E5: ="UPDATE "&$E$3&" SET New_Location_Id = '"&D5&"' WHERE Legacy_Location_Id = '"&B5&"' AND Data_Folder_Id = '"&$A5&"'" -> UPDATE [MAP].[T_TRANS_LOCATION] SET New_Location_Id = 'CO' WHERE Legacy_Location_Id = '1-88' AND Data_Folder_Id = 'sampl' | F5: =IF(B5<>D5,"Changed","-") -> Changed | G5: =IF(B5="","Hide","-") -> -
A6: sampl | B6: 1-20 | C6: 1-20 New Jersey | D6: NJ | E6: ="UPDATE "&$E$3&" SET New_Location_Id = '"&D6&"' WHERE Legacy_Location_Id = '"&B6&"' AND Data_Folder_Id = '"&$A6&"'" -> UPDATE [MAP].[T_TRANS_LOCATION] SET New_Location_Id = 'NJ' WHERE Legacy_Location_Id = '1-20' AND Data_Folder_Id = 'sampl' | F6: =IF(B6<>D6,"Changed","-") -> Changed | G6: =IF(B6="","Hide","-") -> -
A7: sampl | B7: 1-25 | C7: 1-25 Other | D7: OT | E7: ="UPDATE "&$E$3&" SET New_Location_Id = '"&D7&"' WHERE Legacy_Location_Id = '"&B7&"' AND Data_Folder_Id = '"&$A7&"'" -> UPDATE [MAP].[T_TRANS_LOCATION] SET New_Location_Id = 'OT' WHERE Legacy_Location_Id = '1-25' AND Data_Folder_Id = 'sampl' | F7: =IF(B7<>D7,"Changed","-") -> Changed | G7: =IF(B7="","Hide","-") -> -
A8: sampl | B8: 1-10 | C8: 1-10 Pennsylvania | D8: PA | E8: ="UPDATE "&$E$3&" SET New_Location_Id = '"&D8&"' WHERE Legacy_Location_Id = '"&B8&"' AND Data_Folder_Id = '"&$A8&"'" -> UPDATE [MAP].[T_TRANS_LOCATION] SET New_Location_Id = 'PA' WHERE Legacy_Location_Id = '1-10' AND Data_Folder_Id = 'sampl' | F8: =IF(B8<>D8,"Changed","-") -> Changed | G8: =IF(B8="","Hide","-") -> -
A9: sampl | B9: 1-15 | C9: 1-15 West Virginia | D9: WV | E9: ="UPDATE "&$E$3&" SET New_Location_Id = '"&D9&"' WHERE Legacy_Location_Id = '"&B9&"' AND Data_Folder_Id = '"&$A9&"'" -> UPDATE [MAP].[T_TRANS_LOCATION] SET New_Location_Id = 'WV' WHERE Legacy_Location_Id = '1-15' AND Data_Folder_Id = 'sampl' | F9: =IF(B9<>D9,"Changed","-") -> Changed | G9: =IF(B9="","Hide","-") -> -
A10: sampl | B10: 1-99 | C10: 1-99 SUSPENSE | E10: ="UPDATE "&$E$3&" SET New_Location_Id = '"&D10&"' WHERE Legacy_Location_Id = '"&B10&"' AND Data_Folder_Id = '"&$A10&"'" -> UPDATE [MAP].[T_TRANS_LOCATION] SET New_Location_Id = '' WHERE Legacy_Location_Id = '1-99' AND Data_Folder_Id = 'sampl' | F10: =IF(B10<>D10,"Changed","-") -> Changed | G10: =IF(B10="","Hide","-") -> -

Sheet Department ID
A1: ="Legacy ERP: "&Controls!$B$2 -> Legacy ERP: Sage 300 CRE | D1: ="New ERP: "&Controls!$B$3 -> New ERP: Sage Intacct
A3: Data Folder ID | B3: Department | C3: Department Description | D3: Department | E3: [MAP].[T_TRANS_DEPARTMENT] | F3: Change | G3: hide/show
A4: sampl | D4: E010 | E4: ="UPDATE "&$E$3&" SET New_Department_Id = '"&D4&"' WHERE Legacy_Department_Id = '"&B4&"' AND Data_Folder_Id = '"&$A4&"'" -> UPDATE [MAP].[T_TRANS_DEPARTMENT] SET New_Department_Id = 'E010' WHERE Legacy_Department_Id = '' AND Data_Folder_Id = 'sampl' | F4: =IF(B4<>D4,"Changed","-") -> Changed | G4: =IF(B4="","Hide","-") -> Hide
A5: sampl | D5: CO | E5: ="UPDATE "&$E$3&" SET New_Department_Id = '"&D5&"' WHERE Legacy_Department_Id = '"&B5&"' AND Data_Folder_Id = '"&$A5&"'" -> UPDATE [MAP].[T_TRANS_DEPARTMENT] SET New_Department_Id = 'CO' WHERE Legacy_Department_Id = '' AND Data_Folder_Id = 'sampl' | F5: =IF(A5<>B5,"Changed","-") -> Changed | G5: =IF(B5="","Hide","-") -> Hide
A6: sampl | D6: NJ | E6: ="UPDATE "&$E$3&" SET New_Department_Id = '"&D6&"' WHERE Legacy_Department_Id = '"&B6&"' AND Data_Folder_Id = '"&$A6&"'" -> UPDATE [MAP].[T_TRANS_DEPARTMENT] SET New_Department_Id = 'NJ' WHERE Legacy_Department_Id = '' AND Data_Folder_Id = 'sampl' | F6: =IF(A6<>B6,"Changed","-") -> Changed | G6: =IF(B6="","Hide","-") -> Hide
A7: sampl | D7: OT | E7: ="UPDATE "&$E$3&" SET New_Department_Id = '"&D7&"' WHERE Legacy_Department_Id = '"&B7&"' AND Data_Folder_Id = '"&$A7&"'" -> UPDATE [MAP].[T_TRANS_DEPARTMENT] SET New_Department_Id = 'OT' WHERE Legacy_Department_Id = '' AND Data_Folder_Id = 'sampl' | F7: =IF(A7<>B7,"Changed","-") -> Changed | G7: =IF(B7="","Hide","-") -> Hide

Sheet Class ID
A1: ="Legacy ERP: "&Controls!$B$2 -> Legacy ERP: Sage 300 CRE | D1: ="New ERP: "&Controls!$B$3 -> New ERP: Sage Intacct
A3: Data Folder ID | B3: Class | C3: Class Description | D3: Class | E3: [MAP].[T_TRANS_CLASS] | F3: Change | G3: hide/show
A4: sampl | B4: 330MONTAGE | C4: 330 Montage Mountain Road LLC | D4: V0002 | E4: ="UPDATE "&$E$3&" SET NEW_CLASS_ID = '"&D4&"' WHERE LEGACY_CLASS_ID = '"&B4&"' AND DATA_FOLDER_ID = '"&$A4&"'" -> UPDATE [MAP].[T_TRANS_CLASS] SET NEW_CLASS_ID = 'V0002' WHERE LEGACY_CLASS_ID = '330MONTAGE' AND DATA_FOLDER_ID = 'sampl' | F4: =IF(B4<>D4,"Changed","-") -> Changed | G4: =IF(B4="","Hide","-") -> -
A5: sampl | B5: 84LUMBER | C5: 84 Lumber | D5: V0003 | E5: ="UPDATE "&$E$3&" SET NEW_CLASS_ID = '"&D5&"' WHERE LEGACY_CLASS_ID = '"&B5&"' AND DATA_FOLDER_ID = '"&$A5&"'" -> UPDATE [MAP].[T_TRANS_CLASS] SET NEW_CLASS_ID = 'V0003' WHERE LEGACY_CLASS_ID = '84LUMBER' AND DATA_FOLDER_ID = 'sampl' | F5: =IF(B5<>D5,"Changed","-") -> Changed | G5: =IF(B5="","Hide","-") -> -

Sheet Vendor ID
A1: ="Legacy ERP: "&Controls!$B$2 -> Legacy ERP: Sage 300 CRE | D1: ="New ERP: "&Controls!$B$3 -> New ERP: Sage Intacct
A3: Data Folder ID | B3: Vendor | C3: Vendor Description | D3: Vendor | E3: [MAP].[T_TRANS_VENDOR] | F3: Change | G3: hide/show
A4: sampl | B4: 330MONTAGE | C4: 330 Montage Mountain Road LLC | D4: V0002 | E4: ="UPDATE "&$E$3&" SET NEW_VENDOR_ID = '"&D4&"' WHERE LEGACY_VENDOR_ID = '"&B4&"' AND DATA_FOLDER_ID = '"&$A4&"'" -> UPDATE [MAP].[T_TRANS_VENDOR] SET NEW_VENDOR_ID = 'V0002' WHERE LEGACY_VENDOR_ID = '330MONTAGE' AND DATA_FOLDER_ID = 'sampl' | F4: =IF(B4<>D4,"Changed","-") -> Changed | G4: =IF(B4="","Hide","-") -> -
A5: sampl | B5: 84LUMBER | C5: 84 Lumber | D5: V0003 | E5: ="UPDATE "&$E$3&" SET NEW_VENDOR_ID = '"&D5&"' WHERE LEGACY_VENDOR_ID = '"&B5&"' AND DATA_FOLDER_ID = '"&$A5&"'" -> UPDATE [MAP].[T_TRANS_VENDOR] SET NEW_VENDOR_ID = 'V0003' WHERE LEGACY_VENDOR_ID = '84LUMBER' AND DATA_FOLDER_ID = 'sampl' | F5: =IF(B5<>D5,"Changed","-") -> Changed | G5: =IF(B5="","Hide","-") -> -
A6: sampl | B6: A&AAUTOP | C6: A&A Auto Parts Stores Inc | D6: V0004 | E6: ="UPDATE "&$E$3&" SET NEW_VENDOR_ID = '"&D6&"' WHERE LEGACY_VENDOR_ID = '"&B6&"' AND DATA_FOLDER_ID = '"&$A6&"'" -> UPDATE [MAP].[T_TRANS_VENDOR] SET NEW_VENDOR_ID = 'V0004' WHERE LEGACY_VENDOR_ID = 'A&AAUTOP' AND DATA_FOLDER_ID = 'sampl' | F6: =IF(B6<>D6,"Changed","-") -> Changed | G6: =IF(B6="","Hide","-") -> -
A7: sampl | B7: A&BDOORI | C7: A&B Door Sales & Service | D7: V0005 | E7: ="UPDATE "&$E$3&" SET NEW_VENDOR_ID = '"&D7&"' WHERE LEGACY_VENDOR_ID = '"&B7&"' AND DATA_FOLDER_ID = '"&$A7&"'" -> UPDATE [MAP].[T_TRANS_VENDOR] SET NEW_VENDOR_ID = 'V0005' WHERE LEGACY_VENDOR_ID = 'A&BDOORI' AND DATA_FOLDER_ID = 'sampl' | F7: =IF(B7<>D7,"Changed","-") -> Changed | G7: =IF(B7="","Hide","-") -> -
A8: sampl | B8: ABBINC | C8: ABB Inc | D8: V0006 | E8: ="UPDATE "&$E$3&" SET NEW_VENDOR_ID = '"&D8&"' WHERE LEGACY_VENDOR_ID = '"&B8&"' AND DATA_FOLDER_ID = '"&$A8&"'" -> UPDATE [MAP].[T_TRANS_VENDOR] SET NEW_VENDOR_ID = 'V0006' WHERE LEGACY_VENDOR_ID = 'ABBINC' AND DATA_FOLDER_ID = 'sampl' | F8: =IF(B8<>D8,"Changed","-") -> Changed | G8: =IF(B8="","Hide","-") -> -
A9: sampl | B9: ABCSUPPL | C9: ABC Supply Co Inc | D9: V0007 | E9: ="UPDATE "&$E$3&" SET NEW_VENDOR_ID = '"&D9&"' WHERE LEGACY_VENDOR_ID = '"&B9&"' AND DATA_FOLDER_ID = '"&$A9&"'" -> UPDATE [MAP].[T_TRANS_VENDOR] SET NEW_VENDOR_ID = 'V0007' WHERE LEGACY_VENDOR_ID = 'ABCSUPPL' AND DATA_FOLDER_ID = 'sampl' | F9: =IF(B9<>D9,"Changed","-") -> Changed | G9: =IF(B9="","Hide","-") -> -
A10: sampl | B10: ACCORDAN | C10: Accordant Company LLC | D10: V0008 | E10: ="UPDATE "&$E$3&" SET NEW_VENDOR_ID = '"&D10&"' WHERE LEGACY_VENDOR_ID = '"&B10&"' AND DATA_FOLDER_ID = '"&$A10&"'" -> UPDATE [MAP].[T_TRANS_VENDOR] SET NEW_VENDOR_ID = 'V0008' WHERE LEGACY_VENDOR_ID = 'ACCORDAN' AND DATA_FOLDER_ID = 'sampl' | F10: =IF(B10<>D10,"Changed","-") -> Changed | G10: =IF(B10="","Hide","-") -> -
A11: sampl | B11: acculock | C11: Accurate Locksmith | D11: V0009 | E11: ="UPDATE "&$E$3&" SET NEW_VENDOR_ID = '"&D11&"' WHERE LEGACY_VENDOR_ID = '"&B11&"' AND DATA_FOLDER_ID = '"&$A11&"'" -> UPDATE [MAP].[T_TRANS_VENDOR] SET NEW_VENDOR_ID = 'V0009' WHERE LEGACY_VENDOR_ID = 'acculock' AND DATA_FOLDER_ID = 'sampl' | F11: =IF(B11<>D11,"Changed","-") -> Changed | G11: =IF(B11="","Hide","-") -> -
A12: sampl | B12: ACOUSTIC | C12: ACOUSTICAL SPRAY INSULATION | D12: V0010 | E12: ="UPDATE "&$E$3&" SET NEW_VENDOR_ID = '"&D12&"' WHERE LEGACY_VENDOR_ID = '"&B12&"' AND DATA_FOLDER_ID = '"&$A12&"'" -> UPDATE [MAP].[T_TRANS_VENDOR] SET NEW_VENDOR_ID = 'V0010' WHERE LEGACY_VENDOR_ID = 'ACOUSTIC' AND DATA_FOLDER_ID = 'sampl' | F12: =IF(B12<>D12,"Changed","-") -> Changed | G12: =IF(B12="","Hide","-") -> -
A13: sampl | B13: ACSI0000 | C13: Air Cleaning Systems, Inc. | D13: V0011 | E13: ="UPDATE "&$E$3&" SET NEW_VENDOR_ID = '"&D13&"' WHERE LEGACY_VENDOR_ID = '"&B13&"' AND DATA_FOLDER_ID = '"&$A13&"'" -> UPDATE [MAP].[T_TRANS_VENDOR] SET NEW_VENDOR_ID = 'V0011' WHERE LEGACY_VENDOR_ID = 'ACSI0000' AND DATA_FOLDER_ID = 'sampl' | F13: =IF(B13<>D13,"Changed","-") -> Changed | G13: =IF(B13="","Hide","-") -> -
A14: sampl | B14: ACTADAMS | C14: Action Adam Services | D14: V0012 | E14: ="UPDATE "&$E$3&" SET NEW_VENDOR_ID = '"&D14&"' WHERE LEGACY_VENDOR_ID = '"&B14&"' AND DATA_FOLDER_ID = '"&$A14&"'" -> UPDATE [MAP].[T_TRANS_VENDOR] SET NEW_VENDOR_ID = 'V0012' WHERE LEGACY_VENDOR_ID = 'ACTADAMS' AND DATA_FOLDER_ID = 'sampl' | F14: =IF(B14<>D14,"Changed","-") -> Changed | G14: =IF(B14="","Hide","-") -> -
A15: sampl | B15: ACTIONLI | C15: Action Lift Inc | D15: V0013 | E15: ="UPDATE "&$E$3&" SET NEW_VENDOR_ID = '"&D15&"' WHERE LEGACY_VENDOR_ID = '"&B15&"' AND DATA_FOLDER_ID = '"&$A15&"'" -> UPDATE [MAP].[T_TRANS_VENDOR] SET NEW_VENDOR_ID = 'V0013' WHERE LEGACY_VENDOR_ID = 'ACTIONLI' AND DATA_FOLDER_ID = 'sampl' | F15: =IF(B15<>D15,"Changed","-") -> Changed | G15: =IF(B15="","Hide","-") -> -
... A1005: sampl | B1005: ABSTEEL | C1005: AB Steel | D1005: V1043 | E1005: ="UPDATE "&$E$3&" SET NEW_VENDOR_ID = '"&D1005&"' WHERE LEGACY_VENDOR_ID = '"&B1005&"' AND DATA_FOLDER_ID = '"&$A1005&"'" -> UPDATE [MAP].[T_TRANS_VENDOR] SET NEW_VENDOR_ID = 'V1043' WHERE LEGACY_VENDOR_ID = 'ABSTEEL' AND DATA_FOLDER_ID = 'sampl' | F1005: =IF(B1005<>D1005,"Changed","-") -> Changed | G1005: =IF(B1005="","Hide","-") -> -

Sheet Customer ID
A1: ="Legacy ERP: "&Controls!$B$2 -> Legacy ERP: Sage 300 CRE | D1: ="New ERP: "&Controls!$B$3 -> New ERP: Sage Intacct
A3: Data Folder ID | B3: Customer | C3: Customer Description | D3: Customer | E3: [MAP].[T_TRANS_CUSTOMER] | F3: Change | G3: hide/show
A4: sampl | B4: 330Monta | C4: 330 Montage Mountain Road LLC | D4: C0001 | E4: ="UPDATE "&$E$3&" SET NEW_CUSTOMER_ID = '"&D4&"' WHERE LEGACY_CUSTOMER_ID = '"&B4&"' AND DATA_FOLDER_ID = '"&$A4&"'" -> UPDATE [MAP].[T_TRANS_CUSTOMER] SET NEW_CUSTOMER_ID = 'C0001' WHERE LEGACY_CUSTOMER_ID = '330Monta' AND DATA_FOLDER_ID = 'sampl' | F4: =IF(B4<>D4,"Changed","-") -> Changed | G4: =IF(B4="","Hide","-") -> -
A5: sampl | B5: ADAPTIMM | C5: Adaptimmune LLC | D5: C0002 | E5: ="UPDATE "&$E$3&" SET NEW_CUSTOMER_ID = '"&D5&"' WHERE LEGACY_CUSTOMER_ID = '"&B5&"' AND DATA_FOLDER_ID = '"&$A5&"'" -> UPDATE [MAP].[T_TRANS_CUSTOMER] SET NEW_CUSTOMER_ID = 'C0002' WHERE LEGACY_CUSTOMER_ID = 'ADAPTIMM' AND DATA_FOLDER_ID = 'sampl' | F5: =IF(B5<>D5,"Changed","-") -> Changed | G5: =IF(B5="","Hide","-") -> -
A6: sampl | B6: ALTASCIE | C6: Altasciences Pre-Clinical Scranton | D6: C0003 | E6: ="UPDATE "&$E$3&" SET NEW_CUSTOMER_ID = '"&D6&"' WHERE LEGACY_CUSTOMER_ID = '"&B6&"' AND DATA_FOLDER_ID = '"&$A6&"'" -> UPDATE [MAP].[T_TRANS_CUSTOMER] SET NEW_CUSTOMER_ID = 'C0003' WHERE LEGACY_CUSTOMER_ID = 'ALTASCIE' AND DATA_FOLDER_ID = 'sampl' | F6: =IF(B6<>D6,"Changed","-") -> Changed | G6: =IF(B6="","Hide","-") -> -
A7: sampl | B7: AMERICAN | C7: American Custom Drying | D7: C0004 | E7: ="UPDATE "&$E$3&" SET NEW_CUSTOMER_ID = '"&D7&"' WHERE LEGACY_CUSTOMER_ID = '"&B7&"' AND DATA_FOLDER_ID = '"&$A7&"'" -> UPDATE [MAP].[T_TRANS_CUSTOMER] SET NEW_CUSTOMER_ID = 'C0004' WHERE LEGACY_CUSTOMER_ID = 'AMERICAN' AND DATA_FOLDER_ID = 'sampl' | F7: =IF(B7<>D7,"Changed","-") -> Changed | G7: =IF(B7="","Hide","-") -> -
A8: sampl | B8: AUTOTECH | C8: Autotech Concrete | D8: C0005 | E8: ="UPDATE "&$E$3&" SET NEW_CUSTOMER_ID = '"&D8&"' WHERE LEGACY_CUSTOMER_ID = '"&B8&"' AND DATA_FOLDER_ID = '"&$A8&"'" -> UPDATE [MAP].[T_TRANS_CUSTOMER] SET NEW_CUSTOMER_ID = 'C0005' WHERE LEGACY_CUSTOMER_ID = 'AUTOTECH' AND DATA_FOLDER_ID = 'sampl' | F8: =IF(B8<>D8,"Changed","-") -> Changed | G8: =IF(B8="","Hide","-") -> -
A9: sampl | B9: AVPQTA00 | C9: AVP QTA, LLC | D9: C0006 | E9: ="UPDATE "&$E$3&" SET NEW_CUSTOMER_ID = '"&D9&"' WHERE LEGACY_CUSTOMER_ID = '"&B9&"' AND DATA_FOLDER_ID = '"&$A9&"'" -> UPDATE [MAP].[T_TRANS_CUSTOMER] SET NEW_CUSTOMER_ID = 'C0006' WHERE LEGACY_CUSTOMER_ID = 'AVPQTA00' AND DATA_FOLDER_ID = 'sampl' | F9: =IF(B9<>D9,"Changed","-") -> Changed | G9: =IF(B9="","Hide","-") -> -
A10: sampl | B10: BALLCORP | C10: Ball Corporation | D10: C0007 | E10: ="UPDATE "&$E$3&" SET NEW_CUSTOMER_ID = '"&D10&"' WHERE LEGACY_CUSTOMER_ID = '"&B10&"' AND DATA_FOLDER_ID = '"&$A10&"'" -> UPDATE [MAP].[T_TRANS_CUSTOMER] SET NEW_CUSTOMER_ID = 'C0007' WHERE LEGACY_CUSTOMER_ID = 'BALLCORP' AND DATA_FOLDER_ID = 'sampl' | F10: =IF(B10<>D10,"Changed","-") -> Changed | G10: =IF(B10="","Hide","-") -> -
A11: sampl | B11: BEDACOMP | C11: BEDA Company Inc | D11: C0008 | E11: ="UPDATE "&$E$3&" SET NEW_CUSTOMER_ID = '"&D11&"' WHERE LEGACY_CUSTOMER_ID = '"&B11&"' AND DATA_FOLDER_ID = '"&$A11&"'" -> UPDATE [MAP].[T_TRANS_CUSTOMER] SET NEW_CUSTOMER_ID = 'C0008' WHERE LEGACY_CUSTOMER_ID = 'BEDACOMP' AND DATA_FOLDER_ID = 'sampl' | F11: =IF(B11<>D11,"Changed","-") -> Changed | G11: =IF(B11="","Hide","-") -> -
A12: sampl | B12: BEINKE | C12: FR Beinke Wrecking Inc | D12: C0009 | E12: ="UPDATE "&$E$3&" SET NEW_CUSTOMER_ID = '"&D12&"' WHERE LEGACY_CUSTOMER_ID = '"&B12&"' AND DATA_FOLDER_ID = '"&$A12&"'" -> UPDATE [MAP].[T_TRANS_CUSTOMER] SET NEW_CUSTOMER_ID = 'C0009' WHERE LEGACY_CUSTOMER_ID = 'BEINKE' AND DATA_FOLDER_ID = 'sampl' | F12: =IF(B12<>D12,"Changed","-") -> Changed | G12: =IF(B12="","Hide","-") -> -
A13: sampl | B13: BILFINGE | C13: Bilfinger Industrial Services | D13: C0010 | E13: ="UPDATE "&$E$3&" SET NEW_CUSTOMER_ID = '"&D13&"' WHERE LEGACY_CUSTOMER_ID = '"&B13&"' AND DATA_FOLDER_ID = '"&$A13&"'" -> UPDATE [MAP].[T_TRANS_CUSTOMER] SET NEW_CUSTOMER_ID = 'C0010' WHERE LEGACY_CUSTOMER_ID = 'BILFINGE' AND DATA_FOLDER_ID = 'sampl' | F13: =IF(B13<>D13,"Changed","-") -> Changed | G13: =IF(B13="","Hide","-") -> -
A14: sampl | B14: BMPROPTY | C14: B&M Property Development LLC | D14: C0011 | E14: ="UPDATE "&$E$3&" SET NEW_CUSTOMER_ID = '"&D14&"' WHERE LEGACY_CUSTOMER_ID = '"&B14&"' AND DATA_FOLDER_ID = '"&$A14&"'" -> UPDATE [MAP].[T_TRANS_CUSTOMER] SET NEW_CUSTOMER_ID = 'C0011' WHERE LEGACY_CUSTOMER_ID = 'BMPROPTY' AND DATA_FOLDER_ID = 'sampl' | F14: =IF(B14<>D14,"Changed","-") -> Changed | G14: =IF(B14="","Hide","-") -> -
A15: sampl | B15: BORTONLA | C15: Verdantas LLC | D15: C0012 | E15: ="UPDATE "&$E$3&" SET NEW_CUSTOMER_ID = '"&D15&"' WHERE LEGACY_CUSTOMER_ID = '"&B15&"' AND DATA_FOLDER_ID = '"&$A15&"'" -> UPDATE [MAP].[T_TRANS_CUSTOMER] SET NEW_CUSTOMER_ID = 'C0012' WHERE LEGACY_CUSTOMER_ID = 'BORTONLA' AND DATA_FOLDER_ID = 'sampl' | F15: =IF(B15<>D15,"Changed","-") -> Changed | G15: =IF(B15="","Hide","-") -> -
... A126: sampl | B126: MILLTOWN | C126: Milltown Onsite Generation LLC | D126: C0123 | E126: ="UPDATE "&$E$3&" SET NEW_CUSTOMER_ID = '"&D126&"' WHERE LEGACY_CUSTOMER_ID = '"&B126&"' AND DATA_FOLDER_ID = '"&$A126&"'" -> UPDATE [MAP].[T_TRANS_CUSTOMER] SET NEW_CUSTOMER_ID = 'C0123' WHERE LEGACY_CUSTOMER_ID = 'MILLTOWN' AND DATA_FOLDER_ID = 'sampl' | F126: =IF(B126<>D126,"Changed","-") -> Changed | G126: =IF(B126="","Hide","-") -> -

Sheet Cost Code ID
A1: ="Legacy ERP: "&Controls!$B$2 -> Legacy ERP: Sage 300 CRE | D1: ="New ERP: "&Controls!$B$3 -> New ERP: Sage Intacct
A3: Data Folder ID | B3: Cost Code | C3: Cost Code Description | D3: Cost Code | E3: Item ID | F3: [MAP].[T_TRANS_COST_CODE] | G3: Change | H3: hide/show
A4: sampl | B4: 01-0000 | C4: GENERAL REQUIREMENTS | D4: 01-0000 | F4: ="UPDATE "&F$3&" SET NEW_COST_CODE_ID = '"&D4&"', NEW_ITEM_ID = '"&E4&"' WHERE LEGACY_COST_CODE_ID = '"&B4&"' AND DATA_FOLDER_ID = '"&A4&"'" -> UPDATE [MAP].[T_TRANS_COST_CODE] SET NEW_COST_CODE_ID = '01-0000', NEW_ITEM_ID = ' ' WHERE LEGACY_COST_CODE_ID = '01-0000' AND DATA_FOLDER_ID = 'sampl' | G4: =IF(B4<>D4,"Changed","-") -> - | H4: =IF(B4="","Hide","-") -> -
A5: sampl | B5: 01-1005 | C5: Precon Project Executive | D5: 01-1005 | E5: Contract Item | F5: ="UPDATE "&F$3&" SET NEW_COST_CODE_ID = '"&D5&"', NEW_ITEM_ID = '"&E5&"' WHERE LEGACY_COST_CODE_ID = '"&B5&"' AND DATA_FOLDER_ID = '"&A5&"'" -> UPDATE [MAP].[T_TRANS_COST_CODE] SET NEW_COST_CODE_ID = '01-1005', NEW_ITEM_ID = 'Contract Item' WHERE LEGACY_COST_CODE_ID = '01-1005' AND DATA_FOLDER_ID = 'sampl' | G5: =IF(B5<>D5,"Changed","-") -> - | H5: =IF(B5="","Hide","-") -> -
A6: sampl | B6: 01-1008 | C6: Precon Senior Project Manager | D6: 01-1008 | E6: Contract Item | F6: ="UPDATE "&F$3&" SET NEW_COST_CODE_ID = '"&D6&"', NEW_ITEM_ID = '"&E6&"' WHERE LEGACY_COST_CODE_ID = '"&B6&"' AND DATA_FOLDER_ID = '"&A6&"'" -> UPDATE [MAP].[T_TRANS_COST_CODE] SET NEW_COST_CODE_ID = '01-1008', NEW_ITEM_ID = 'Contract Item' WHERE LEGACY_COST_CODE_ID = '01-1008' AND DATA_FOLDER_ID = 'sampl' | G6: =IF(B6<>D6,"Changed","-") -> - | H6: =IF(B6="","Hide","-") -> -
A7: sampl | B7: 01-1010 | C7: Precon Project Manager | D7: 01-1010 | E7: Contract Item | F7: ="UPDATE "&F$3&" SET NEW_COST_CODE_ID = '"&D7&"', NEW_ITEM_ID = '"&E7&"' WHERE LEGACY_COST_CODE_ID = '"&B7&"' AND DATA_FOLDER_ID = '"&A7&"'" -> UPDATE [MAP].[T_TRANS_COST_CODE] SET NEW_COST_CODE_ID = '01-1010', NEW_ITEM_ID = 'Contract Item' WHERE LEGACY_COST_CODE_ID = '01-1010' AND DATA_FOLDER_ID = 'sampl' | G7: =IF(B7<>D7,"Changed","-") -> - | H7: =IF(B7="","Hide","-") -> -
A8: sampl | B8: 01-1012 | C8: Precon Project Manager Assist | D8: 01-1212 | E8: Contract Item | F8: ="UPDATE "&F$3&" SET NEW_COST_CODE_ID = '"&D8&"', NEW_ITEM_ID = '"&E8&"' WHERE LEGACY_COST_CODE_ID = '"&B8&"' AND DATA_FOLDER_ID = '"&A8&"'" -> UPDATE [MAP].[T_TRANS_COST_CODE] SET NEW_COST_CODE_ID = '01-1212', NEW_ITEM_ID = 'Contract Item' WHERE LEGACY_COST_CODE_ID = '01-1012' AND DATA_FOLDER_ID = 'sampl' | G8: =IF(B8<>D8,"Changed","-") -> Changed | H8: =IF(B8="","Hide","-") -> -
A9: sampl | B9: 01-1015 | C9: Precon Construction Manager | D9: 01-1015 | E9: Contract Item | F9: ="UPDATE "&F$3&" SET NEW_COST_CODE_ID = '"&D9&"', NEW_ITEM_ID = '"&E9&"' WHERE LEGACY_COST_CODE_ID = '"&B9&"' AND DATA_FOLDER_ID = '"&A9&"'" -> UPDATE [MAP].[T_TRANS_COST_CODE] SET NEW_COST_CODE_ID = '01-1015', NEW_ITEM_ID = 'Contract Item' WHERE LEGACY_COST_CODE_ID = '01-1015' AND DATA_FOLDER_ID = 'sampl' | G9: =IF(B9<>D9,"Changed","-") -> - | H9: =IF(B9="","Hide","-") -> -
A10: sampl | B10: 01-1016 | C10: Precon Construction Mgr Senior | D10: 01-1016 | E10: Contract Item | F10: ="UPDATE "&F$3&" SET NEW_COST_CODE_ID = '"&D10&"', NEW_ITEM_ID = '"&E10&"' WHERE LEGACY_COST_CODE_ID = '"&B10&"' AND DATA_FOLDER_ID = '"&A10&"'" -> UPDATE [MAP].[T_TRANS_COST_CODE] SET NEW_COST_CODE_ID = '01-1016', NEW_ITEM_ID = 'Contract Item' WHERE LEGACY_COST_CODE_ID = '01-1016' AND DATA_FOLDER_ID = 'sampl' | G10: =IF(B10<>D10,"Changed","-") -> - | H10: =IF(B10="","Hide","-") -> -
A11: sampl | B11: 01-1020 | C11: Precon Superintendent | D11: 01-1020 | E11: Contract Item | F11: ="UPDATE "&F$3&" SET NEW_COST_CODE_ID = '"&D11&"', NEW_ITEM_ID = '"&E11&"' WHERE LEGACY_COST_CODE_ID = '"&B11&"' AND DATA_FOLDER_ID = '"&A11&"'" -> UPDATE [MAP].[T_TRANS_COST_CODE] SET NEW_COST_CODE_ID = '01-1020', NEW_ITEM_ID = 'Contract Item' WHERE LEGACY_COST_CODE_ID = '01-1020' AND DATA_FOLDER_ID = 'sampl' | G11: =IF(B11<>D11,"Changed","-") -> - | H11: =IF(B11="","Hide","-") -> -
A12: sampl | B12: 01-1025 | C12: Precon Business Development | D12: 01-1025 | E12: Contract Item | F12: ="UPDATE "&F$3&" SET NEW_COST_CODE_ID = '"&D12&"', NEW_ITEM_ID = '"&E12&"' WHERE LEGACY_COST_CODE_ID = '"&B12&"' AND DATA_FOLDER_ID = '"&A12&"'" -> UPDATE [MAP].[T_TRANS_COST_CODE] SET NEW_COST_CODE_ID = '01-1025', NEW_ITEM_ID = 'Contract Item' WHERE LEGACY_COST_CODE_ID = '01-1025' AND DATA_FOLDER_ID = 'sampl' | G12: =IF(B12<>D12,"Changed","-") -> - | H12: =IF(B12="","Hide","-") -> -
A13: sampl | B13: 01-1030 | C13: Precon Safety Coordinator | D13: 01-1030 | E13: Contract Item | F13: ="UPDATE "&F$3&" SET NEW_COST_CODE_ID = '"&D13&"', NEW_ITEM_ID = '"&E13&"' WHERE LEGACY_COST_CODE_ID = '"&B13&"' AND DATA_FOLDER_ID = '"&A13&"'" -> UPDATE [MAP].[T_TRANS_COST_CODE] SET NEW_COST_CODE_ID = '01-1030', NEW_ITEM_ID = 'Contract Item' WHERE LEGACY_COST_CODE_ID = '01-1030' AND DATA_FOLDER_ID = 'sampl' | G13: =IF(B13<>D13,"Changed","-") -> - | H13: =IF(B13="","Hide","-") -> -
A14: sampl | B14: 01-1040 | C14: Precon Project Engineer | D14: 01-1040 | E14: Contract Item | F14: ="UPDATE "&F$3&" SET NEW_COST_CODE_ID = '"&D14&"', NEW_ITEM_ID = '"&E14&"' WHERE LEGACY_COST_CODE_ID = '"&B14&"' AND DATA_FOLDER_ID = '"&A14&"'" -> UPDATE [MAP].[T_TRANS_COST_CODE] SET NEW_COST_CODE_ID = '01-1040', NEW_ITEM_ID = 'Contract Item' WHERE LEGACY_COST_CODE_ID = '01-1040' AND DATA_FOLDER_ID = 'sampl' | G14: =IF(B14<>D14,"Changed","-") -> - | H14: =IF(B14="","Hide","-") -> -
A15: sampl | B15: 01-1045 | C15: Precon Quality Control Manager | D15: 01-1045 | E15: Contract Item | F15: ="UPDATE "&F$3&" SET NEW_COST_CODE_ID = '"&D15&"', NEW_ITEM_ID = '"&E15&"' WHERE LEGACY_COST_CODE_ID = '"&B15&"' AND DATA_FOLDER_ID = '"&A15&"'" -> UPDATE [MAP].[T_TRANS_COST_CODE] SET NEW_COST_CODE_ID = '01-1045', NEW_ITEM_ID = 'Contract Item' WHERE LEGACY_COST_CODE_ID = '01-1045' AND DATA_FOLDER_ID = 'sampl' | G15: =IF(B15<>D15,"Changed","-") -> - | H15: =IF(B15="","Hide","-") -> -
A16: sampl | B16: 01-1050 | C16: Precon Project Assistant | D16: 01-1050 | E16: Contract Item | F16: ="UPDATE "&F$3&" SET NEW_COST_CODE_ID = '"&D16&"', NEW_ITEM_ID = '"&E16&"' WHERE LEGACY_COST_CODE_ID = '"&B16&"' AND DATA_FOLDER_ID = '"&A16&"'" -> UPDATE [MAP].[T_TRANS_COST_CODE] SET NEW_COST_CODE_ID = '01-1050', NEW_ITEM_ID = 'Contract Item' WHERE LEGACY_COST_CODE_ID = '01-1050' AND DATA_FOLDER_ID = 'sampl' | G16: =IF(B16<>D16,"Changed","-") -> - | H16: =IF(B16="","Hide","-") -> -
... A39: sampl | B39: 01-1210 | C39: Layout | D39: 01-1215 | E39: Contract Item | F39: ="UPDATE "&F$3&" SET NEW_COST_CODE_ID = '"&D39&"', NEW_ITEM_ID = '"&E39&"' WHERE LEGACY_COST_CODE_ID = '"&B39&"' AND DATA_FOLDER_ID = '"&A39&"'" -> UPDATE [MAP].[T_TRANS_COST_CODE] SET NEW_COST_CODE_ID = '01-1215', NEW_ITEM_ID = 'Contract Item' WHERE LEGACY_COST_CODE_ID = '01-1210' AND DATA_FOLDER_ID = 'sampl' | G39: =IF(B39<>D39,"Changed","-") -> Changed | H39: =IF(B39="","Hide","-") -> -
A40: sampl | B40: 01-1215 | F40: ="UPDATE "&F$3&" SET NEW_COST_CODE_ID = '"&D40&"', NEW_ITEM_ID = '"&E40&"' WHERE LEGACY_COST_CODE_ID = '"&B40&"' AND DATA_FOLDER_ID = '"&A40&"'" -> UPDATE [MAP].[T_TRANS_COST_CODE] SET NEW_COST_CODE_ID = '', NEW_ITEM_ID = '' WHERE LEGACY_COST_CODE_ID = '01-1215' AND DATA_FOLDER_ID = 'sampl' | G40: =IF(B40<>D40,"Changed","-") -> Changed | H40: =IF(B40="","Hide","-") -> -
A41: sampl | B41: 01-1220 | C41: Safety Requirements | D41: 01-1220 | E41: Contract Item | F41: ="UPDATE "&F$3&" SET NEW_COST_CODE_ID = '"&D41&"', NEW_ITEM_ID = '"&E41&"' WHERE LEGACY_COST_CODE_ID = '"&B41&"' AND DATA_FOLDER_ID = '"&A41&"'" -> UPDATE [MAP].[T_TRANS_COST_CODE] SET NEW_COST_CODE_ID = '01-1220', NEW_ITEM_ID = 'Contract Item' WHERE LEGACY_COST_CODE_ID = '01-1220' AND DATA_FOLDER_ID = 'sampl' | G41: =IF(B41<>D41,"Changed","-") -> - | H41: =IF(B41="","Hide","-") -> -
A42: sampl | B42: 01-1225 | C42: Field Office Trailer | D42: 01-1225 | E42: Contract Item | F42: ="UPDATE "&F$3&" SET NEW_COST_CODE_ID = '"&D42&"', NEW_ITEM_ID = '"&E42&"' WHERE LEGACY_COST_CODE_ID = '"&B42&"' AND DATA_FOLDER_ID = '"&A42&"'" -> UPDATE [MAP].[T_TRANS_COST_CODE] SET NEW_COST_CODE_ID = '01-1225', NEW_ITEM_ID = 'Contract Item' WHERE LEGACY_COST_CODE_ID = '01-1225' AND DATA_FOLDER_ID = 'sampl' | G42: =IF(B42<>D42,"Changed","-") -> - | H42: =IF(B42="","Hide","-") -> -
A43: sampl | B43: 01-1240 | C43: Storage Trailer | D43: 01-1240 | E43: Contract Item | F43: ="UPDATE "&F$3&" SET NEW_COST_CODE_ID = '"&D43&"', NEW_ITEM_ID = '"&E43&"' WHERE LEGACY_COST_CODE_ID = '"&B43&"' AND DATA_FOLDER_ID = '"&A43&"'" -> UPDATE [MAP].[T_TRANS_COST_CODE] SET NEW_COST_CODE_ID = '01-1240', NEW_ITEM_ID = 'Contract Item' WHERE LEGACY_COST_CODE_ID = '01-1240' AND DATA_FOLDER_ID = 'sampl' | G43: =IF(B43<>D43,"Changed","-") -> - | H43: =IF(B43="","Hide","-") -> -
A44: sampl | B44: 01-1245 | C44: Job Security | D44: 01-1245 | E44: Contract Item | F44: ="UPDATE "&F$3&" SET NEW_COST_CODE_ID = '"&D44&"', NEW_ITEM_ID = '"&E44&"' WHERE LEGACY_COST_CODE_ID = '"&B44&"' AND DATA_FOLDER_ID = '"&A44&"'" -> UPDATE [MAP].[T_TRANS_COST_CODE] SET NEW_COST_CODE_ID = '01-1245', NEW_ITEM_ID = 'Contract Item' WHERE LEGACY_COST_CODE_ID = '01-1245' AND DATA_FOLDER_ID = 'sampl' | G44: =IF(B44<>D44,"Changed","-") -> - | H44: =IF(B44="","Hide","-") -> -
A45: sampl | B45: 01-1250 | C45: Photographs | D45: 01-1250 | E45: Contract Item | F45: ="UPDATE "&F$3&" SET NEW_COST_CODE_ID = '"&D45&"', NEW_ITEM_ID = '"&E45&"' WHERE LEGACY_COST_CODE_ID = '"&B45&"' AND DATA_FOLDER_ID = '"&A45&"'" -> UPDATE [MAP].[T_TRANS_COST_CODE] SET NEW_COST_CODE_ID = '01-1250', NEW_ITEM_ID = 'Contract Item' WHERE LEGACY_COST_CODE_ID = '01-1250' AND DATA_FOLDER_ID = 'sampl' | G45: =IF(B45<>D45,"Changed","-") -> - | H45: =IF(B45="","Hide","-") -> -
A46: sampl | B46: 01-1255 | C46: Shipping | D46: 01-1255 | E46: Contract Item | F46: ="UPDATE "&F$3&" SET NEW_COST_CODE_ID = '"&D46&"', NEW_ITEM_ID = '"&E46&"' WHERE LEGACY_COST_CODE_ID = '"&B46&"' AND DATA_FOLDER_ID = '"&A46&"'" -> UPDATE [MAP].[T_TRANS_COST_CODE] SET NEW_COST_CODE_ID = '01-1255', NEW_ITEM_ID = 'Contract Item' WHERE LEGACY_COST_CODE_ID = '01-1255' AND DATA_FOLDER_ID = 'sampl' | G46: =IF(B46<>D46,"Changed","-") -> - | H46: =IF(B46="","Hide","-") -> -
A47: sampl | B47: 01-1260 | C47: Drawings Reproduction | D47: 01-1260 | E47: Contract Item | F47: ="UPDATE "&F$3&" SET NEW_COST_CODE_ID = '"&D47&"', NEW_ITEM_ID = '"&E47&"' WHERE LEGACY_COST_CODE_ID = '"&B47&"' AND DATA_FOLDER_ID = '"&A47&"'" -> UPDATE [MAP].[T_TRANS_COST_CODE] SET NEW_COST_CODE_ID = '01-1260', NEW_ITEM_ID = 'Contract Item' WHERE LEGACY_COST_CODE_ID = '01-1260' AND DATA_FOLDER_ID = 'sampl' | G47: =IF(B47<>D47,"Changed","-") -> - | H47: =IF(B47="","Hide","-") -> -
A48: sampl | B48: 01-1265 | C48: Small Tools | D48: 01-1265 | E48: Contract Item | F48: ="UPDATE "&F$3&" SET NEW_COST_CODE_ID = '"&D48&"', NEW_ITEM_ID = '"&E48&"' WHERE LEGACY_COST_CODE_ID = '"&B48&"' AND DATA_FOLDER_ID = '"&A48&"'" -> UPDATE [MAP].[T_TRANS_COST_CODE] SET NEW_COST_CODE_ID = '01-1265', NEW_ITEM_ID = 'Contract Item' WHERE LEGACY_COST_CODE_ID = '01-1265' AND DATA_FOLDER_ID = 'sampl' | G48: =IF(B48<>D48,"Changed","-") -> - | H48: =IF(B48="","Hide","-") -> -
A49: sampl | B49: 01-1270 | C49: Current Clean-up | D49: 01-1270 | E49: Contract Item | F49: ="UPDATE "&F$3&" SET NEW_COST_CODE_ID = '"&D49&"', NEW_ITEM_ID = '"&E49&"' WHERE LEGACY_COST_CODE_ID = '"&B49&"' AND DATA_FOLDER_ID = '"&A49&"'" -> UPDATE [MAP].[T_TRANS_COST_CODE] SET NEW_COST_CODE_ID = '01-1270', NEW_ITEM_ID = 'Contract Item' WHERE LEGACY_COST_CODE_ID = '01-1270' AND DATA_FOLDER_ID = 'sampl' | G49: =IF(B49<>D49,"Changed","-") -> - | H49: =IF(B49="","Hide","-") -> -
A50: sampl | B50: 01-1275 | C50: Dumpsters | D50: 01-1275 | E50: Contract Item | F50: ="UPDATE "&F$3&" SET NEW_COST_CODE_ID = '"&D50&"', NEW_ITEM_ID = '"&E50&"' WHERE LEGACY_COST_CODE_ID = '"&B50&"' AND DATA_FOLDER_ID = '"&A50&"'" -> UPDATE [MAP].[T_TRANS_COST_CODE] SET NEW_COST_CODE_ID = '01-1275', NEW_ITEM_ID = 'Contract Item' WHERE LEGACY_COST_CODE_ID = '01-1275' AND DATA_FOLDER_ID = 'sampl' | G50: =IF(B50<>D50,"Changed","-") -> - | H50: =IF(B50="","Hide","-") -> -
A51: sampl | B51: 01-1300 | C51: Legal Fees | D51: 01-1300 | E51: Contract Item | F51: ="UPDATE "&F$3&" SET NEW_COST_CODE_ID = '"&D51&"', NEW_ITEM_ID = '"&E51&"' WHERE LEGACY_COST_CODE_ID = '"&B51&"' AND DATA_FOLDER_ID = '"&A51&"'" -> UPDATE [MAP].[T_TRANS_COST_CODE] SET NEW_COST_CODE_ID = '01-1300', NEW_ITEM_ID = 'Contract Item' WHERE LEGACY_COST_CODE_ID = '01-1300' AND DATA_FOLDER_ID = 'sampl' | G51: =IF(B51<>D51,"Changed","-") -> - | H51: =IF(B51="","Hide","-") -> -
A52: sampl | B52: 01-1305 | C52: Architectural Engineering Serv | D52: 01-1305 | E52: Contract Item | F52: ="UPDATE "&F$3&" SET NEW_COST_CODE_ID = '"&D52&"', NEW_ITEM_ID = '"&E52&"' WHERE LEGACY_COST_CODE_ID = '"&B52&"' AND DATA_FOLDER_ID = '"&A52&"'" -> UPDATE [MAP].[T_TRANS_COST_CODE] SET NEW_COST_CODE_ID = '01-1305', NEW_ITEM_ID = 'Contract Item' WHERE LEGACY_COST_CODE_ID = '01-1305' AND DATA_FOLDER_ID = 'sampl' | G52: =IF(B52<>D52,"Changed","-") -> - | H52: =IF(B52="","Hide","-") -> -
... A81: sampl | B81: 01-5123 | C81: Temp Heat, Cooling & Vent | D81: 01-5123 | E81: Contract Item | F81: ="UPDATE "&F$3&" SET NEW_COST_CODE_ID = '"&D81&"', NEW_ITEM_ID = '"&E81&"' WHERE LEGACY_COST_CODE_ID = '"&B81&"' AND DATA_FOLDER_ID = '"&A81&"'" -> UPDATE [MAP].[T_TRANS_COST_CODE] SET NEW_COST_CODE_ID = '01-5123', NEW_ITEM_ID = 'Contract Item' WHERE LEGACY_COST_CODE_ID = '01-5123' AND DATA_FOLDER_ID = 'sampl' | G81: =IF(B81<>D81,"Changed","-") -> - | H81: =IF(B81="","Hide","-") -> -
A82: sampl | B82: 02-0000 | C82: EXISTING CONDITIONS | D82: 02-0000 | F82: ="UPDATE "&F$3&" SET NEW_COST_CODE_ID = '"&D82&"', NEW_ITEM_ID = '"&E82&"' WHERE LEGACY_COST_CODE_ID = '"&B82&"' AND DATA_FOLDER_ID = '"&A82&"'" -> UPDATE [MAP].[T_TRANS_COST_CODE] SET NEW_COST_CODE_ID = '02-0000', NEW_ITEM_ID = ' ' WHERE LEGACY_COST_CODE_ID = '02-0000' AND DATA_FOLDER_ID = 'sampl' | G82: =IF(B82<>D82,"Changed","-") -> - | H82: =IF(B82="","Hide","-") -> -
A83: sampl | B83: 02-3000 | C83: Subsurface Investigation | D83: 02-3000 | E83: Contract Item | F83: ="UPDATE "&F$3&" SET NEW_COST_CODE_ID = '"&D83&"', NEW_ITEM_ID = '"&E83&"' WHERE LEGACY_COST_CODE_ID = '"&B83&"' AND DATA_FOLDER_ID = '"&A83&"'" -> UPDATE [MAP].[T_TRANS_COST_CODE] SET NEW_COST_CODE_ID = '02-3000', NEW_ITEM_ID = 'Contract Item' WHERE LEGACY_COST_CODE_ID = '02-3000' AND DATA_FOLDER_ID = 'sampl' | G83: =IF(B83<>D83,"Changed","-") -> - | H83: =IF(B83="","Hide","-") -> -
A84: sampl | B84: 02-4113 | C84: Selective Site Demolition | D84: 02-4113 | E84: Contract Item | F84: ="UPDATE "&F$3&" SET NEW_COST_CODE_ID = '"&D84&"', NEW_ITEM_ID = '"&E84&"' WHERE LEGACY_COST_CODE_ID = '"&B84&"' AND DATA_FOLDER_ID = '"&A84&"'" -> UPDATE [MAP].[T_TRANS_COST_CODE] SET NEW_COST_CODE_ID = '02-4113', NEW_ITEM_ID = 'Contract Item' WHERE LEGACY_COST_CODE_ID = '02-4113' AND DATA_FOLDER_ID = 'sampl' | G84: =IF(B84<>D84,"Changed","-") -> - | H84: =IF(B84="","Hide","-") -> -
A85: sampl | B85: 02-4116 | C85: Structure Demolition | D85: 02-4116 | E85: Contract Item | F85: ="UPDATE "&F$3&" SET NEW_COST_CODE_ID = '"&D85&"', NEW_ITEM_ID = '"&E85&"' WHERE LEGACY_COST_CODE_ID = '"&B85&"' AND DATA_FOLDER_ID = '"&A85&"'" -> UPDATE [MAP].[T_TRANS_COST_CODE] SET NEW_COST_CODE_ID = '02-4116', NEW_ITEM_ID = 'Contract Item' WHERE LEGACY_COST_CODE_ID = '02-4116' AND DATA_FOLDER_ID = 'sampl' | G85: =IF(B85<>D85,"Changed","-") -> - | H85: =IF(B85="","Hide","-") -> -
A86: sampl | B86: 02-4119 | C86: Selective Demolition | D86: 02-4119 | E86: Contract Item | F86: ="UPDATE "&F$3&" SET NEW_COST_CODE_ID = '"&D86&"', NEW_ITEM_ID = '"&E86&"' WHERE LEGACY_COST_CODE_ID = '"&B86&"' AND DATA_FOLDER_ID = '"&A86&"'" -> UPDATE [MAP].[T_TRANS_COST_CODE] SET NEW_COST_CODE_ID = '02-4119', NEW_ITEM_ID = 'Contract Item' WHERE LEGACY_COST_CODE_ID = '02-4119' AND DATA_FOLDER_ID = 'sampl' | G86: =IF(B86<>D86,"Changed","-") -> - | H86: =IF(B86="","Hide","-") -> -
A87: sampl | B87: 02-4901 | C87: Flatwork Concrete Removal | D87: 02-4901 | E87: Contract Item | F87: ="UPDATE "&F$3&" SET NEW_COST_CODE_ID = '"&D87&"', NEW_ITEM_ID = '"&E87&"' WHERE LEGACY_COST_CODE_ID = '"&B87&"' AND DATA_FOLDER_ID = '"&A87&"'" -> UPDATE [MAP].[T_TRANS_COST_CODE] SET NEW_COST_CODE_ID = '02-4901', NEW_ITEM_ID = 'Contract Item' WHERE LEGACY_COST_CODE_ID = '02-4901' AND DATA_FOLDER_ID = 'sampl' | G87: =IF(B87<>D87,"Changed","-") -> - | H87: =IF(B87="","Hide","-") -> -
A88: sampl | B88: 02-4902 | C88: Structural Concrete Removal | D88: 02-4902 | E88: Contract Item | F88: ="UPDATE "&F$3&" SET NEW_COST_CODE_ID = '"&D88&"', NEW_ITEM_ID = '"&E88&"' WHERE LEGACY_COST_CODE_ID = '"&B88&"' AND DATA_FOLDER_ID = '"&A88&"'" -> UPDATE [MAP].[T_TRANS_COST_CODE] SET NEW_COST_CODE_ID = '02-4902', NEW_ITEM_ID = 'Contract Item' WHERE LEGACY_COST_CODE_ID = '02-4902' AND DATA_FOLDER_ID = 'sampl' | G88: =IF(B88<>D88,"Changed","-") -> - | H88: =IF(B88="","Hide","-") -> -
A89: sampl | B89: 02-4903 | C89: Concrete Demolition | D89: 02-4903 | E89: Contract Item | F89: ="UPDATE "&F$3&" SET NEW_COST_CODE_ID = '"&D89&"', NEW_ITEM_ID = '"&E89&"' WHERE LEGACY_COST_CODE_ID = '"&B89&"' AND DATA_FOLDER_ID = '"&A89&"'" -> UPDATE [MAP].[T_TRANS_COST_CODE] SET NEW_COST_CODE_ID = '02-4903', NEW_ITEM_ID = 'Contract Item' WHERE LEGACY_COST_CODE_ID = '02-4903' AND DATA_FOLDER_ID = 'sampl' | G89: =IF(B89<>D89,"Changed","-") -> - | H89: =IF(B89="","Hide","-") -> -
A90: sampl | B90: 02-4904 | C90: Masonry Demolition | D90: 02-4904 | E90: Contract Item | F90: ="UPDATE "&F$3&" SET NEW_COST_CODE_ID = '"&D90&"', NEW_ITEM_ID = '"&E90&"' WHERE LEGACY_COST_CODE_ID = '"&B90&"' AND DATA_FOLDER_ID = '"&A90&"'" -> UPDATE [MAP].[T_TRANS_COST_CODE] SET NEW_COST_CODE_ID = '02-4904', NEW_ITEM_ID = 'Contract Item' WHERE LEGACY_COST_CODE_ID = '02-4904' AND DATA_FOLDER_ID = 'sampl' | G90: =IF(B90<>D90,"Changed","-") -> - | H90: =IF(B90="","Hide","-") -> -
A91: sampl | B91: 02-4905 | C91: Steel Demolition | D91: 02-4905 | E91: Contract Item | F91: ="UPDATE "&F$3&" SET NEW_COST_CODE_ID = '"&D91&"', NEW_ITEM_ID = '"&E91&"' WHERE LEGACY_COST_CODE_ID = '"&B91&"' AND DATA_FOLDER_ID = '"&A91&"'" -> UPDATE [MAP].[T_TRANS_COST_CODE] SET NEW_COST_CODE_ID = '02-4905', NEW_ITEM_ID = 'Contract Item' WHERE LEGACY_COST_CODE_ID = '02-4905' AND DATA_FOLDER_ID = 'sampl' | G91: =IF(B91<>D91,"Changed","-") -> - | H91: =IF(B91="","Hide","-") -> -
...

Sheet Cost Type ID
A1: ="Legacy ERP: "&Controls!$B$2 -> Legacy ERP: Sage 300 CRE | D1: ="New ERP: "&Controls!$B$3 -> New ERP: Sage Intacct
A3: Data Folder ID | B3: Cost Type | C3: Cost Type Description | D3: Cost Type | E3: Item ID | F3: GL Account | G3: [MAP].[T_TRANS_COST_TYPE] | H3: Change | I3: hide/show
A4: sampl | B4: E | C4: Equipment Rented | D4: E | E4: E | F4: 5205 | G4: ="UPDATE "&G$3&" SET NEW_COST_TYPE_ID = '"&D4&"', NEW_ITEM_ID = '"&E4&"', NEW_INTACCT_GL_ACCOUNT = '"&F4&"' WHERE LEGACY_COST_TYPE_ID = '"&B4&"' AND DATA_FOLDER_ID = '"&A4&"'" -> UPDATE [MAP].[T_TRANS_COST_TYPE] SET NEW_COST_TYPE_ID = 'E', NEW_ITEM_ID = 'E', NEW_INTACCT_GL_ACCOUNT = '5205' WHERE LEGACY_COST_TYPE_ID = 'E' AND DATA_FOLDER_ID = 'sampl' | H4: =IF(B4<>D4,"Changed","-") -> - | I4: =IF(B4="","Hide","-") -> -
A5: sampl | B5: EO | C5: Equipment Owned | D5: EO | E5: EO | F5: 5200 | G5: ="UPDATE "&G$3&" SET NEW_COST_TYPE_ID = '"&D5&"', NEW_ITEM_ID = '"&E5&"', NEW_INTACCT_GL_ACCOUNT = '"&F5&"' WHERE LEGACY_COST_TYPE_ID = '"&B5&"' AND DATA_FOLDER_ID = '"&A5&"'" -> UPDATE [MAP].[T_TRANS_COST_TYPE] SET NEW_COST_TYPE_ID = 'EO', NEW_ITEM_ID = 'EO', NEW_INTACCT_GL_ACCOUNT = '5200' WHERE LEGACY_COST_TYPE_ID = 'EO' AND DATA_FOLDER_ID = 'sampl' | H5: =IF(B5<>D5,"Changed","-") -> - | I5: =IF(B5="","Hide","-") -> -
A6: sampl | B6: FT | C6: Freight & Sales Tax | D6: FT | E6: FT | F6: 5100 | G6: ="UPDATE "&G$3&" SET NEW_COST_TYPE_ID = '"&D6&"', NEW_ITEM_ID = '"&E6&"', NEW_INTACCT_GL_ACCOUNT = '"&F6&"' WHERE LEGACY_COST_TYPE_ID = '"&B6&"' AND DATA_FOLDER_ID = '"&A6&"'" -> UPDATE [MAP].[T_TRANS_COST_TYPE] SET NEW_COST_TYPE_ID = 'FT', NEW_ITEM_ID = 'FT', NEW_INTACCT_GL_ACCOUNT = '5100' WHERE LEGACY_COST_TYPE_ID = 'FT' AND DATA_FOLDER_ID = 'sampl' | H6: =IF(B6<>D6,"Changed","-") -> - | I6: =IF(B6="","Hide","-") -> -
A7: sampl | B7: IDE | C7: Insurance Dental Employee (DNU) | D7: IDE | E7: L | F7: 5020 | G7: ="UPDATE "&G$3&" SET NEW_COST_TYPE_ID = '"&D7&"', NEW_ITEM_ID = '"&E7&"', NEW_INTACCT_GL_ACCOUNT = '"&F7&"' WHERE LEGACY_COST_TYPE_ID = '"&B7&"' AND DATA_FOLDER_ID = '"&A7&"'" -> UPDATE [MAP].[T_TRANS_COST_TYPE] SET NEW_COST_TYPE_ID = 'IDE', NEW_ITEM_ID = 'L', NEW_INTACCT_GL_ACCOUNT = '5020' WHERE LEGACY_COST_TYPE_ID = 'IDE' AND DATA_FOLDER_ID = 'sampl' | H7: =IF(B7<>D7,"Changed","-") -> - | I7: =IF(B7="","Hide","-") -> -
A8: sampl | B8: IDI | C8: Insurance STD Employee (DNU) | D8: IDI | E8: L | F8: 5020 | G8: ="UPDATE "&G$3&" SET NEW_COST_TYPE_ID = '"&D8&"', NEW_ITEM_ID = '"&E8&"', NEW_INTACCT_GL_ACCOUNT = '"&F8&"' WHERE LEGACY_COST_TYPE_ID = '"&B8&"' AND DATA_FOLDER_ID = '"&A8&"'" -> UPDATE [MAP].[T_TRANS_COST_TYPE] SET NEW_COST_TYPE_ID = 'IDI', NEW_ITEM_ID = 'L', NEW_INTACCT_GL_ACCOUNT = '5020' WHERE LEGACY_COST_TYPE_ID = 'IDI' AND DATA_FOLDER_ID = 'sampl' | H8: =IF(B8<>D8,"Changed","-") -> - | I8: =IF(B8="","Hide","-") -> -
A9: sampl | B9: IHE | C9: Insurance Health Employee (DNU) | D9: IHE | E9: L | F9: 5020 | G9: ="UPDATE "&G$3&" SET NEW_COST_TYPE_ID = '"&D9&"', NEW_ITEM_ID = '"&E9&"', NEW_INTACCT_GL_ACCOUNT = '"&F9&"' WHERE LEGACY_COST_TYPE_ID = '"&B9&"' AND DATA_FOLDER_ID = '"&A9&"'" -> UPDATE [MAP].[T_TRANS_COST_TYPE] SET NEW_COST_TYPE_ID = 'IHE', NEW_ITEM_ID = 'L', NEW_INTACCT_GL_ACCOUNT = '5020' WHERE LEGACY_COST_TYPE_ID = 'IHE' AND DATA_FOLDER_ID = 'sampl' | H9: =IF(B9<>D9,"Changed","-") -> - | I9: =IF(B9="","Hide","-") -> -
A10: sampl | B10: ILI | C10: Insurance Life Employee (DNU) | D10: ILI | E10: L | F10: 5020 | G10: ="UPDATE "&G$3&" SET NEW_COST_TYPE_ID = '"&D10&"', NEW_ITEM_ID = '"&E10&"', NEW_INTACCT_GL_ACCOUNT = '"&F10&"' WHERE LEGACY_COST_TYPE_ID = '"&B10&"' AND DATA_FOLDER_ID = '"&A10&"'" -> UPDATE [MAP].[T_TRANS_COST_TYPE] SET NEW_COST_TYPE_ID = 'ILI', NEW_ITEM_ID = 'L', NEW_INTACCT_GL_ACCOUNT = '5020' WHERE LEGACY_COST_TYPE_ID = 'ILI' AND DATA_FOLDER_ID = 'sampl' | H10: =IF(B10<>D10,"Changed","-") -> - | I10: =IF(B10="","Hide","-") -> -
A11: sampl | B11: L | C11: Labor | D11: L | E11: L | F11: 5000 | G11: ="UPDATE "&G$3&" SET NEW_COST_TYPE_ID = '"&D11&"', NEW_ITEM_ID = '"&E11&"', NEW_INTACCT_GL_ACCOUNT = '"&F11&"' WHERE LEGACY_COST_TYPE_ID = '"&B11&"' AND DATA_FOLDER_ID = '"&A11&"'" -> UPDATE [MAP].[T_TRANS_COST_TYPE] SET NEW_COST_TYPE_ID = 'L', NEW_ITEM_ID = 'L', NEW_INTACCT_GL_ACCOUNT = '5000' WHERE LEGACY_COST_TYPE_ID = 'L' AND DATA_FOLDER_ID = 'sampl' | H11: =IF(B11<>D11,"Changed","-") -> - | I11: =IF(B11="","Hide","-") -> -
A12: sampl | B12: LFT | C12: FICA Withholding Tax (DNU) | D12: LFT | E12: L | F12: 5005 | G12: ="UPDATE "&G$3&" SET NEW_COST_TYPE_ID = '"&D12&"', NEW_ITEM_ID = '"&E12&"', NEW_INTACCT_GL_ACCOUNT = '"&F12&"' WHERE LEGACY_COST_TYPE_ID = '"&B12&"' AND DATA_FOLDER_ID = '"&A12&"'" -> UPDATE [MAP].[T_TRANS_COST_TYPE] SET NEW_COST_TYPE_ID = 'LFT', NEW_ITEM_ID = 'L', NEW_INTACCT_GL_ACCOUNT = '5005' WHERE LEGACY_COST_TYPE_ID = 'LFT' AND DATA_FOLDER_ID = 'sampl' | H12: =IF(B12<>D12,"Changed","-") -> - | I12: =IF(B12="","Hide","-") -> -
A13: sampl | B13: LFU | C13: FUTA Unemployment Tax (DNU) | D13: LFU | E13: L | F13: 5005 | G13: ="UPDATE "&G$3&" SET NEW_COST_TYPE_ID = '"&D13&"', NEW_ITEM_ID = '"&E13&"', NEW_INTACCT_GL_ACCOUNT = '"&F13&"' WHERE LEGACY_COST_TYPE_ID = '"&B13&"' AND DATA_FOLDER_ID = '"&A13&"'" -> UPDATE [MAP].[T_TRANS_COST_TYPE] SET NEW_COST_TYPE_ID = 'LFU', NEW_ITEM_ID = 'L', NEW_INTACCT_GL_ACCOUNT = '5005' WHERE LEGACY_COST_TYPE_ID = 'LFU' AND DATA_FOLDER_ID = 'sampl' | H13: =IF(B13<>D13,"Changed","-") -> - | I13: =IF(B13="","Hide","-") -> -
A14: sampl | B14: LPS | C14: Pension Profit Sharing (DNU) | D14: LPS | E14: L | F14: 5010 | G14: ="UPDATE "&G$3&" SET NEW_COST_TYPE_ID = '"&D14&"', NEW_ITEM_ID = '"&E14&"', NEW_INTACCT_GL_ACCOUNT = '"&F14&"' WHERE LEGACY_COST_TYPE_ID = '"&B14&"' AND DATA_FOLDER_ID = '"&A14&"'" -> UPDATE [MAP].[T_TRANS_COST_TYPE] SET NEW_COST_TYPE_ID = 'LPS', NEW_ITEM_ID = 'L', NEW_INTACCT_GL_ACCOUNT = '5010' WHERE LEGACY_COST_TYPE_ID = 'LPS' AND DATA_FOLDER_ID = 'sampl' | H14: =IF(B14<>D14,"Changed","-") -> - | I14: =IF(B14="","Hide","-") -> -
A15: sampl | B15: LSD | C15: State Disability Insurance (DNU) | D15: LSD | E15: L | F15: 5005 | G15: ="UPDATE "&G$3&" SET NEW_COST_TYPE_ID = '"&D15&"', NEW_ITEM_ID = '"&E15&"', NEW_INTACCT_GL_ACCOUNT = '"&F15&"' WHERE LEGACY_COST_TYPE_ID = '"&B15&"' AND DATA_FOLDER_ID = '"&A15&"'" -> UPDATE [MAP].[T_TRANS_COST_TYPE] SET NEW_COST_TYPE_ID = 'LSD', NEW_ITEM_ID = 'L', NEW_INTACCT_GL_ACCOUNT = '5005' WHERE LEGACY_COST_TYPE_ID = 'LSD' AND DATA_FOLDER_ID = 'sampl' | H15: =IF(B15<>D15,"Changed","-") -> - | I15: =IF(B15="","Hide","-") -> -
... A26: sampl | B26: S | C26: Subcontractors | D26: S | E26: S | F26: 5110 | G26: ="UPDATE "&G$3&" SET NEW_COST_TYPE_ID = '"&D26&"', NEW_ITEM_ID = '"&E26&"', NEW_INTACCT_GL_ACCOUNT = '"&F26&"' WHERE LEGACY_COST_TYPE_ID = '"&B26&"' AND DATA_FOLDER_ID = '"&A26&"'" -> UPDATE [MAP].[T_TRANS_COST_TYPE] SET NEW_COST_TYPE_ID = 'S', NEW_ITEM_ID = 'S', NEW_INTACCT_GL_ACCOUNT = '5110' WHERE LEGACY_COST_TYPE_ID = 'S' AND DATA_FOLDER_ID = 'sampl' | H26: =IF(B26<>D26,"Changed","-") -> - | I26: =IF(B26="","Hide","-") -> -

Sheet Employee ID
A1: ="Legacy ERP: "&Controls!$B$2 -> Legacy ERP: Sage 300 CRE | D1: ="New ERP: "&Controls!$B$3 -> New ERP: Sage Intacct
A3: Data Folder ID | B3: Employee | C3: Employee Description | D3: Employee | E3: [MAP].[T_TRANS_EMPLOYEE] | F3: Change | G3: hide/show
A4: sampl | B4: EE1 | C4: John Smith | D4: E0001 | E4: ="UPDATE "&$E$3&" SET NEW_EMPLOYEE_ID = '"&D4&"' WHERE LEGACY_EMPLOYEE_ID = '"&B4&"' AND DATA_FOLDER_ID = '"&$A4&"'" -> UPDATE [MAP].[T_TRANS_EMPLOYEE] SET NEW_EMPLOYEE_ID = 'E0001' WHERE LEGACY_EMPLOYEE_ID = 'EE1' AND DATA_FOLDER_ID = 'sampl' | F4: =IF(B4<>D4,"Changed","-") -> Changed | G4: =IF(B4="","Hide","-") -> -
A5: sampl | B5: EE2 | C5: James Smith | D5: E0002 | E5: ="UPDATE "&$E$3&" SET NEW_EMPLOYEE_ID = '"&D5&"' WHERE LEGACY_EMPLOYEE_ID = '"&B5&"' AND DATA_FOLDER_ID = '"&$A5&"'" -> UPDATE [MAP].[T_TRANS_EMPLOYEE] SET NEW_EMPLOYEE_ID = 'E0002' WHERE LEGACY_EMPLOYEE_ID = 'EE2' AND DATA_FOLDER_ID = 'sampl' | F5: =IF(B5<>D5,"Changed","-") -> Changed | G5: =IF(B5="","Hide","-") -> -
A6: sampl | B6: EE3 | C6: Kathy Smith | D6: E0003 | E6: ="UPDATE "&$E$3&" SET NEW_EMPLOYEE_ID = '"&D6&"' WHERE LEGACY_EMPLOYEE_ID = '"&B6&"' AND DATA_FOLDER_ID = '"&$A6&"'" -> UPDATE [MAP].[T_TRANS_EMPLOYEE] SET NEW_EMPLOYEE_ID = 'E0003' WHERE LEGACY_EMPLOYEE_ID = 'EE3' AND DATA_FOLDER_ID = 'sampl' | F6: =IF(B6<>D6,"Changed","-") -> Changed | G6: =IF(B6="","Hide","-") -> -

Sheet Inventory Item ID
A1: ="Legacy ERP: "&Controls!$B$2 -> Legacy ERP: Sage 300 CRE | D1: ="New ERP: "&Controls!$B$3 -> New ERP: Sage Intacct
A3: Data Folder ID | B3: Inventory Item | C3: Inventory Item Description | D3: Inventory Item | E3: [MAP].[T_TRANS_ITEM] | F3: Change | G3: hide/show
A4: sampl | B4: 00123546 | C4: Widget A | D4: ITM-001 | E4: ="UPDATE "&$E$3&" SET NEW_ITEM_ID = '"&D4&"' WHERE LEGACY_ITEM_ID = '"&B4&"' AND DATA_FOLDER_ID = '"&$A4&"'" -> UPDATE [MAP].[T_TRANS_ITEM] SET NEW_ITEM_ID = 'ITM-001' WHERE LEGACY_ITEM_ID = '00123546' AND DATA_FOLDER_ID = 'sampl' | F4: =IF(B4<>D4,"Changed","-") -> Changed | G4: =IF(B4="","Hide","-") -> -
A5: sampl | B5: 00123567 | C5: Widget B | D5: ITM-002 | E5: ="UPDATE "&$E$3&" SET NEW_ITEM_ID = '"&D5&"' WHERE LEGACY_ITEM_ID = '"&B5&"' AND DATA_FOLDER_ID = '"&$A5&"'" -> UPDATE [MAP].[T_TRANS_ITEM] SET NEW_ITEM_ID = 'ITM-002' WHERE LEGACY_ITEM_ID = '00123567' AND DATA_FOLDER_ID = 'sampl' | F5: =IF(B5<>D5,"Changed","-") -> Changed | G5: =IF(B5="","Hide","-") -> -
A6: sampl | B6: 00123568 | C6: Widget C | D6: ITM-003 | E6: ="UPDATE "&$E$3&" SET NEW_ITEM_ID = '"&D6&"' WHERE LEGACY_ITEM_ID = '"&B6&"' AND DATA_FOLDER_ID = '"&$A6&"'" -> UPDATE [MAP].[T_TRANS_ITEM] SET NEW_ITEM_ID = 'ITM-003' WHERE LEGACY_ITEM_ID = '00123568' AND DATA_FOLDER_ID = 'sampl' | F6: =IF(B6<>D6,"Changed","-") -> Changed | G6: =IF(B6="","Hide","-") -> -

Sheet Warehouse ID
A1: ="Legacy ERP: "&Controls!$B$2 -> Legacy ERP: Sage 300 CRE | D1: ="New ERP: "&Controls!$B$3 -> New ERP: Sage Intacct
A3: Data Folder ID | B3: Warehouse | C3: Warehouse Description | D3: Warehouse | E3: Location ID | F3: [MAP].[T_TRANS_WAREHOUSE] | G3: Change | H3: hide/show
A4: sampl | B4: OH123 | C4: Ohio Main | D4: 123 | E4: OH | F4: ="UPDATE "&$F$3&" SET NEW_WAREHOUSE_ID = '"&D4&", NEW_LOCATION_ID = '"&E4&"' WHERE LEGACY_WAREHOUSE_ID = '"&B4&"' AND DATA_FOLDER_ID = '"&$A4&"'" -> UPDATE [MAP].[T_TRANS_WAREHOUSE] SET NEW_WAREHOUSE_ID = '123, NEW_LOCATION_ID = 'OH' WHERE LEGACY_WAREHOUSE_ID = 'OH123' AND DATA_FOLDER_ID = 'sampl' | G4: =IF(B4<>D4,"Changed","-") -> Changed | H4: =IF(B4="","Hide","-") -> -
A5: sampl | B5: FL124 | C5: Florida Main | D5: 124 | E5: FL | F5: ="UPDATE "&$F$3&" SET NEW_WAREHOUSE_ID = '"&D5&", NEW_LOCATION_ID = '"&E5&"' WHERE LEGACY_WAREHOUSE_ID = '"&B5&"' AND DATA_FOLDER_ID = '"&$A5&"'" -> UPDATE [MAP].[T_TRANS_WAREHOUSE] SET NEW_WAREHOUSE_ID = '124, NEW_LOCATION_ID = 'FL' WHERE LEGACY_WAREHOUSE_ID = 'FL124' AND DATA_FOLDER_ID = 'sampl' | G5: =IF(B5<>D5,"Changed","-") -> Changed | H5: =IF(B5="","Hide","-") -> -
A6: sampl | B6: IN125 | C6: Indiana Main | D6: 125 | E6: IN | F6: ="UPDATE "&$F$3&" SET NEW_WAREHOUSE_ID = '"&D6&", NEW_LOCATION_ID = '"&E6&"' WHERE LEGACY_WAREHOUSE_ID = '"&B6&"' AND DATA_FOLDER_ID = '"&$A6&"'" -> UPDATE [MAP].[T_TRANS_WAREHOUSE] SET NEW_WAREHOUSE_ID = '125, NEW_LOCATION_ID = 'IN' WHERE LEGACY_WAREHOUSE_ID = 'IN125' AND DATA_FOLDER_ID = 'sampl' | G6: =IF(B6<>D6,"Changed","-") -> Changed | H6: =IF(B6="","Hide","-") -> -
